Workbook
Name aporte: Principal!$D$21
Name CAGR: Principal!$D$33
Name despesas_mensais: Principal!$D$15
Name investimento_mes: Principal!$C$64
Name juros_patrimonio_inicial: Principal!$D$26
Name patrimonio_final: Principal!$D$29
Name patrimonio_inicial: Principal!$D$20
Name patromonio_viver_renda: Principal!$D$38
Name percentual_investimento: Principal!$C$17
Name percentual_salario_cobberto: Principal!#REF!
Name qtd_anos: Principal!$D$22
Name renda_mensal_estimada: Principal!$D$30
Name rendimento_carteira: Principal!$D$16
Name rendimento_total: Principal!$D$28
Name salario: Principal!$D$14
Name sugestao_investimento: Principal!$D$17
Name taxa_anual: Principal!$D$24
Name taxa_mensal: Principal!$D$23
Name total_investido: Principal!$D$27

Sheet Principal
B1: Versão: v1.0.0 PRO Última atualização: Jan/2026 | N1: Fale conosco
B2: Esta planilha é uma ferramenta educacional e não constitui recomendação de investimento.
B11: Invest Mais PRO – Simule quando você poderá viver de renda
B13: CONFIGURAÇÕES
B14: Salário Líquido | D14: 4200
B15: Gastos Mensais | D15: 3500
B16: Rendimento Carteira por Mês (%) | D16: 0.01
B17: Sugestão de Investimento (30%) | C17: 1 | D17: =IFERROR(salario*percentual_investimento,"Enrada Inválida!!!") -> 4200
B19: INVESTIMENTO MENSAL
B20: Patrimônio Inicial | D20: 20000
B21: Quanto Investir por Mês (Aporte) | D21: 500
B22: Por Quanos Anos | D22: 5
B23: Quanto seu Dinheiro Rende por Mês (%) | D23: =IFERROR(rendimento_carteira,"Enrada Inválida!!!") -> 0.01
B24: Quanto seu Dinheiro Rende por Ano (%) | D24: =IFERROR((taxa_mensal+1)^12-1,"Enrada Inválida!!!") -> 0.12682503
A25: =B25 -> Patrimônio Inicial | B25: =B20 -> Patrimônio Inicial | D25: =patrimonio_inicial -> 20000 | E25: =IF(patrimonio_inicial=0,NA(),patrimonio_inicial) -> 20000
A26: =B26 -> Juros Sobre o Partimônio Inicial | B26: Juros Sobre o Partimônio Inicial | D26: =IFERROR(FV(taxa_mensal,qtd_anos*12,,-patrimonio_inicial)-patrimonio_inicial,"Enrada Inválida!!!") -> 16333.934 | E26: =IF(juros_patrimonio_inicial=0,NA(),juros_patrimonio_inicial) -> 16333.934
A27: =B27 -> Total Invesido (Aporte) | B27: Total Invesido (Aporte) | D27: =IFERROR(PRODUCT(qtd_anos*12,aporte),"Enrada Inválida!!!") -> 30000 | E27: =IF(total_investido=0,NA(),total_investido) -> 30000
A28: =B28 -> Juros Sobre Total Investido (Aportes) | B28: Juros Sobre Total Investido (Aportes) | D28: =IFERROR(patrimonio_final-juros_patrimonio_inicial-patrimonio_inicial-total_investido,"Enrada Inválida!!!") -> 10834.835 | E28: =IF(rendimento_total=0,NA(),rendimento_total) -> 10834.835
A29: =B29 -> Patrimônio Total Projetado | B29: Patrimônio Total Projetado | D29: =IFERROR(FV(taxa_mensal,qtd_anos*12,-aporte)+juros_patrimonio_inicial+patrimonio_inicial,"Enrada Inválida!!!") -> 77168.769 | E29: =IF(patrimonio_final=0,NA(),patrimonio_final) -> 77168.769
A30: =B30 -> Renda Mensal Estimada (Dividendos Estimados) | B30: Renda Mensal Estimada (Dividendos Estimados) | D30: =IFERROR(patrimonio_final*rendimento_carteira,"Enrada Inválida!!!") -> 771.68769
B31: =VALUE(SUBSTITUTE(D39," Ano(s)","")) -> 14.6 | C31: =despesas_mensais -> 3500 | D31: ="Independência Financeira"&CHAR(10)& "📅 "&B31&" anos"&CHAR(10)& "💰 R$ "&TEXT(C31,"#.##0,00") -> Independência Financeira 📅 14,6 anos 💰 R$ 3.500,00
B32: INDICADORES
B33: Percentual do Salário Coberto pelos Dividendos | D33: =IFERROR(renda_mensal_estimada/salario,"Enrada Inválida!!!") -> 0.18373516
B34: Percentual das despesas Coberto pelos Dividendos | D34: =IFERROR(renda_mensal_estimada/despesas_mensais,"Enrada Inválida!!!") -> 0.2204822
B35: Crescimento Médio Real do Patrimônio ao Ano (CAGR) | D35: =IFERROR((patrimonio_final/total_investido)^(1/qtd_anos)-1,"Enrada Inválida!!!") -> 0.20799201
B36: Percentual de Rendimento sobre o Patrimônio Total | D36: =IFERROR(rendimento_total/patrimonio_final,"Enrada Inválida!!!") -> 0.1404044
B37: Índice de eficiência do investimento | D37: =IFERROR(TEXT(rendimento_total/total_investido,"R$ ###.###.##0,00"),"Enrada Inválida!!!") -> R$ 0,36
B38: Patrimônio necessário para viver de renda | D38: =IFERROR(despesas_mensais/rendimento_carteira,"Enrada Inválida!!!") -> 350000
B39: Tempo necessário para viver de renda | D39: =IFERROR(TEXT(NPER(taxa_mensal, -aporte, -patrimonio_inicial, patromonio_viver_renda)/12,"###.###.##0,00 ")&"Ano(s)","Enrada Inválida!!!") -> 14,60 Ano(s)
B40: Tempo para Dobrar o Patrimônio | D40: =IFERROR(TEXT(LN(2)/LN(1+taxa_anual),"###.###.##0,00 ")&"Ano(s)","Enrada Inválida!!!") -> 5,81 Ano(s)
B42: Cenários | C42: Patrimônio Total Projetado | D42: Renda Mensal Estimada | E42: =B15 -> Gastos Mensais
A43: 2 | B43: ="Quanto em "&A43&" anos" -> Quanto em 2 anos | C43: =FV(taxa_mensal,A43*12,-aporte,-patrimonio_inicial) -> 38881.425 | D43: =C43*rendimento_carteira -> 388.81425 | E43: =despesas_mensais -> 3500
A44: 5 | B44: ="Quanto em "&A44&" anos" -> Quanto em 5 anos | C44: =FV(taxa_mensal,A44*12,-aporte,-patrimonio_inicial) -> 77168.769 | D44: =C44*rendimento_carteira -> 771.68769 | E44: =despesas_mensais -> 3500
A45: 10 | B45: ="Quanto em "&A45&" anos" -> Quanto em 10 anos | C45: =FV(taxa_mensal,A45*12,-aporte,-patrimonio_inicial) -> 181027.08 | D45: =C45*rendimento_carteira -> 1810.2708 | E45: =despesas_mensais -> 3500
A46: 15 | B46: ="Quanto em "&A46&" anos" -> Quanto em 15 anos | C46: =FV(taxa_mensal,A46*12,-aporte,-patrimonio_inicial) -> 369706.14 | D46: =C46*rendimento_carteira -> 3697.0614 | E46: =despesas_mensais -> 3500
A47: 20 | B47: ="Quanto em "&A47&" anos" -> Quanto em 20 anos | C47: =FV(taxa_mensal,A47*12,-aporte,-patrimonio_inicial) -> 712478.76 | D47: =C47*rendimento_carteira -> 7124.7876 | E47: =despesas_mensais -> 3500
A48: 25 | B48: ="Quanto em "&A48&" anos" -> Quanto em 25 anos | C48: =FV(taxa_mensal,A48*12,-aporte,-patrimonio_inicial) -> 1335192.6 | D48: =C48*rendimento_carteira -> 13351.926 | E48: =despesas_mensais -> 3500
A49: 30 | B49: ="Quanto em "&A49&" anos" -> Quanto em 30 anos | C49: =FV(taxa_mensal,A49*12,-aporte,-patrimonio_inicial) -> 2466474.9 | D49: =C49*rendimento_carteira -> 24664.749 | E49: =despesas_mensais -> 3500
A50: 35 | B50: ="Quanto em "&A50&" anos" -> Quanto em 35 anos | C50: =FV(taxa_mensal,A50*12,-aporte,-patrimonio_inicial) -> 4521671.6 | D50: =C50*rendimento_carteira -> 45216.716 | E50: =despesas_mensais -> 3500
A51: Anos
...

Sheet Gráfico1

Sheet Gráfico2

Sheet Gráfico3

Sheet Gráfico4

Sheet Gráfico5

Sheet Ajuda
B2: Esta planilha é uma ferramenta educacional e não constitui recomendação de investimento.
B4: Bem-vindo à Planilha Invest Mais PRO - Simulador Financeiro
B6: Esta planilha foi criada para ajudar você a planejar seus investimentos e visualizar o crescimento do seu patrimônio ao longo do tempo.
B8: Como usar | D8: Campos preenchidos pelo usuário (Campos na cor verde claro)
B9: 1. Preencha todos os campos destacados | D9: Campo | E9: Descrição | F9: Regra
B10: 2. Escolha seu perfil de investidor | D10: Salário Líquido | E10: Informe sua renda mensal líquida média | F10: > 0
B11: 3. Informe o valor mensal a ser investido | D11: Gastos Mensais | E11: Total médio dos seus gastos fixos e variáveis | F11: >= 0
B12: 4. Defina o prazo de investimento | D12: Rendimento Carteira por Mês (%) | E12: Percentual médio anual esperado | F12: 0,001% e 999,999%
B13: 5. Analise os gráficos e resultados | D13: Sugestão de Investimento (30%) | E13: Percentual sugerido para investir | F13: 0,01% e 100,00%
D14: Patrimônio Inicial | E14: Valor já investido atualmente | F14: >= 0
B15: Importante | D15: Quanto Investir por Mês | E15: Valor que será aportado mensalmente | F15: > 0
D16: Por Quantos Anos | E16: Horizonte de investimento | F16: > 0
B17: Utilize valores realistas
B18: Revise seus dados periodicamente | D18: O usuário também poderá selecionar o Perfil de Investidor:
B19: Esta planilha é apenas uma simulação | D19: Conservador
D20: Moderado
B21: Observações Importantes | D21: Agressivo
B23: Pequenos aportes feitos de forma consistente podem gerar grandes resultados no longo prazo! | D23: Com base nessas informações, a planilha realiza automaticamente todos os cálculos e gera os gráficos.
B24: Esta planilha tem finalidade educacional e de simulação. Não constitui recomendação de investimento.
B25: Não substitui orientação profissional. | E25: Produto: Planilha Invest Mais PRO - Simulador Financeiro
B26: Resultados são estimativas, não garantias. | E26: Versão: v1.0.0 PRO
E27: Data de lançamento: 01/2026
E28: Autor: Fernando Castro

Sheet Perguntas
A1: Objetivo: Criar um Simulador Simples de Investimento
B2: Quanto investir por mês?
B3: Por quanos anos?
B4: Taxa de rendimento mensal?
B5: Quanto de patrimômio acumulado?
B6: Quanto são os dividendos mensais?

Sheet Cores
C3: Célula Editável | D3: #DAF2D0

Sheet Apoio
A2: CHAVE | B2: PERFIL | C2: Tipo de FII | D2: %
A3: =B3&"-"&C3 -> Conservador-Papel | B3: Conservador | C3: Papel | D3: 0.3
A4: =B4&"-"&C4 -> Conservador-Tijolo | B4: Conservador | C4: Tijolo | D4: 0.5
A5: =B5&"-"&C5 -> Conservador-Híbridos | B5: Conservador | C5: Híbridos | D5: 0.1
A6: =B6&"-"&C6 -> Conservador-FOF's | B6: Conservador | C6: FOF's | D6: 0.1
A7: =B7&"-"&C7 -> Conservador-Desenvolvimento | B7: Conservador | C7: Desenvolvimento | D7: 0
A8: =B8&"-"&C8 -> Conservador-Hotelarias | B8: Conservador | C8: Hotelarias | D8: 0 | E8: =SUM(D3:D8) -> 1
A9: =B9&"-"&C9 -> Moderado-Papel | B9: Moderado | C9: Papel | D9: 0.32
A10: =B10&"-"&C10 -> Moderado-Tijolo | B10: Moderado | C10: Tijolo | D10: 0.35
A11: =B11&"-"&C11 -> Moderado-Híbridos | B11: Moderado | C11: Híbridos | D11: 0.08
A12: =B12&"-"&C12 -> Moderado-FOF's | B12: Moderado | C12: FOF's | D12: 0.05
A13: =B13&"-"&C13 -> Moderado-Desenvolvimento | B13: Moderado | C13: Desenvolvimento | D13: 0.1
A14: =B14&"-"&C14 -> Moderado-Hotelarias | B14: Moderado | C14: Hotelarias | D14: 0.1 | E14: =SUM(D9:D14) -> 1
A15: =B15&"-"&C15 -> Agressivo-Papel | B15: Agressivo | C15: Papel | D15: 0.5
A16: =B16&"-"&C16 -> Agressivo-Tijolo | B16: Agressivo | C16: Tijolo | D16: 0.1
A17: =B17&"-"&C17 -> Agressivo-Híbridos | B17: Agressivo | C17: Híbridos | D17: 0.05
A18: =B18&"-"&C18 -> Agressivo-FOF's | B18: Agressivo | C18: FOF's | D18: 0.05
A19: =B19&"-"&C19 -> Agressivo-Desenvolvimento | B19: Agressivo | C19: Desenvolvimento | D19: 0.2
A20: =B20&"-"&C20 -> Agressivo-Hotelarias | B20: Agressivo | C20: Hotelarias | D20: 0.1 | E20: =SUM(D15:D20) -> 1
